<?xml version="1.0"?>
<robot
  name="SL_assem3">
  <link
    name="Chassis">
    <inertial>
      <origin
        xyz="-1.7085E-06 -0.00016805 -6.005E-05"
        rpy="0 0 0" />
      <mass
        value="0.00015782" />
      <inertia
        ixx="3.148E-09"
        ixy="-5.1759E-14"
        ixz="-2.6324E-13"
        iyy="1.9031E-08"
        iyz="-1.8192E-12"
        izz="1.5888E-08" />
    </inertial>
    <visual>
      <origin
        xyz="0 0 0"
        rpy="0 0 0" />
      <geometry>
        <mesh
          filename="package://SL_assem3/meshes/Chassis.obj" />
      </geometry>
      <material
        name="">
        <color
          rgba="0.75294 0.75294 0.75294 1" />
      </material>
    </visual>
    <collision>
      <origin
        xyz="0 0 0"
        rpy="0 0 0" />
      <geometry>
        <mesh
          filename="package://SL_assem3/meshes/Chassis.obj" />
      </geometry>
    </collision>
  </link>
  <link
    name="FLS1">
    <inertial>
      <origin
        xyz="5.8948E-05 0.0040833 0.0013542"
        rpy="0 0 0" />
      <mass
        value="8.1633E-06" />
      <inertia
        ixx="5.8025E-11"
        ixy="-6.7979E-13"
        ixz="-2.1268E-13"
        iyy="1.0946E-11"
        iyz="-1.4732E-11"
        izz="4.7177E-11" />
    </inertial>
    <visual>
      <origin
        xyz="0 0 0"
        rpy="0 0 0" />
      <geometry>
        <mesh
          filename="package://SL_assem3/meshes/FLS1.obj" />
      </geometry>
      <material
        name="">
        <color
          rgba="0.69804 0.69804 0.69804 1" />
      </material>
    </visual>
    <collision>
      <origin
        xyz="0 0 0"
        rpy="0 0 0" />
      <geometry>
        <mesh
          filename="package://SL_assem3/meshes/FLS1.obj" />
      </geometry>
    </collision>
  </link>
  <joint
    name="FLqsact"
    type="prismatic">
    <origin
      xyz="0.013166 -0.0084525 -0.00049826"
      rpy="0 0 0" />
    <parent
      link="Chassis" />
    <child
      link="FLS1" />
    <axis
      xyz="0.014435 0.9999 0" />
    <limit lower="-0.00015" upper = "0.00015" />
  </joint>
  <link
    name="FLS2">
    <inertial>
      <origin
        xyz="0.00070289 -8.6332E-05 0.00010242"
        rpy="0 0 0" />
      <mass
        value="3.889E-06" />
      <inertia
        ixx="2.6158E-12"
        ixy="-5.7753E-13"
        ixz="-3.2642E-13"
        iyy="4.7809E-12"
        iyz="-8.2188E-14"
        izz="3.1897E-12" />
    </inertial>
    <visual>
      <origin
        xyz="0 0 0"
        rpy="0 0 0" />
      <geometry>
        <mesh
          filename="package://SL_assem3/meshes/FLS2.obj" />
      </geometry>
      <material
        name="">
        <color
          rgba="1 1 1 1" />
      </material>
    </visual>
    <collision>
      <origin
        xyz="0 0 0"
        rpy="0 0 0" />
      <geometry>
        <mesh
          filename="package://SL_assem3/meshes/FLS2.obj" />
      </geometry>
    </collision>
  </link>
  <joint
    name="FLqs1"
    type="revolute">
    <origin
      xyz="0.00011855899505822 0.00821246013088212 0.00218825042921003"
      rpy="0 0 0" />
    <parent
      link="FLS1" />
    <child
      link="FLS2" />
    <axis
      xyz="0 0 -1" />
  </joint>
  <link
    name="FLS3">
    <inertial>
      <origin
        xyz="0.0014605 0.0018371 0.0030882"
        rpy="0 0 0" />
      <mass
        value="1.4269E-05" />
      <inertia
        ixx="1.206E-10"
        ixy="3.2785E-11"
        ixz="-2.9892E-11"
        iyy="8.3598E-11"
        iyz="2.1738E-11"
        izz="9.8829E-11" />
    </inertial>
    <visual>
      <origin
        xyz="0 0 0"
        rpy="0 0 0" />
      <geometry>
        <mesh
          filename="package://SL_assem3/meshes/FLS3.obj" />
      </geometry>
      <material
        name="">
        <color
          rgba="0.69804 0.69804 0.69804 1" />
      </material>
    </visual>
    <collision>
      <origin
        xyz="0 0 0"
        rpy="0 0 0" />
      <geometry>
        <mesh
          filename="package://SL_assem3/meshes/FLS3.obj" />
      </geometry>
    </collision>
  </link>
  <joint
    name="FLqfb1"
    type="revolute">
    <origin
      xyz="0.00152236486486502 0.000119999999999994 -0.00125"
      rpy="0 0 0" />
    <parent
      link="FLS2" />
    <child
      link="FLS3" />
    <axis
      xyz="-1 0 0" />
  </joint>
  <link
    name="FLL1">
    <inertial>
      <origin
        xyz="-0.00026551 0.0033266 5.8575E-05"
        rpy="0 0 0" />
      <mass
        value="6.1384E-06" />
      <inertia
        ixx="2.2378E-11"
        ixy="4.5667E-13"
        ixz="3.1102E-13"
        iyy="5.4007E-12"
        iyz="-1.8286E-12"
        izz="2.4818E-11" />
    </inertial>
    <visual>
      <origin
        xyz="0 0 0"
        rpy="0 0 0" />
      <geometry>
        <mesh
          filename="package://SL_assem3/meshes/FLL1.obj" />
      </geometry>
      <material
        name="">
        <color
          rgba="0.69804 0.69804 0.69804 1" />
      </material>
    </visual>
    <collision>
      <origin
        xyz="0 0 0"
        rpy="0 0 0" />
      <geometry>
        <mesh
          filename="package://SL_assem3/meshes/FLL1.obj" />
      </geometry>
    </collision>
  </link>
  <joint
    name="FLqlact"
    type="prismatic">
    <origin
      xyz="0.0106272965191551 -0.00696134254771869 -0.00081362646611445"
      rpy="0.0449514904502148 3.34687345020587E-15 1.50548364770604E-16" />
    <parent
      link="Chassis" />
    <child
      link="FLL1" />
    <axis
      xyz="-0.212093435026329 0.977249392334798 0" />
    <limit lower="-0.00015" upper = "0.00015" />
  </joint>
  <link
    name="FLL2">
    <inertial>
      <origin
        xyz="0.00011652 8.8187E-05 -0.00056964"
        rpy="0 0 0" />
      <mass
        value="4.2308E-06" />
      <inertia
        ixx="2.753E-12"
        ixy="-1.0699E-13"
        ixz="3.2368E-13"
        iyy="5.862E-12"
        iyz="5.5412E-13"
        izz="4.6521E-12" />
    </inertial>
    <visual>
      <origin
        xyz="0 0 0"
        rpy="0 0 0" />
      <geometry>
        <mesh
          filename="package://SL_assem3/meshes/FLL2.obj" />
      </geometry>
      <material
        name="">
        <color
          rgba="0.69804 0.69804 0.69804 1" />
      </material>
    </visual>
    <collision>
      <origin
        xyz="0 0 0"
        rpy="0 0 0" />
      <geometry>
        <mesh
          filename="package://SL_assem3/meshes/FLL2.obj" />
      </geometry>
    </collision>
  </link>
  <joint
    name="FLql1"
    type="revolute">
    <origin
      xyz="-0.00012263670386452 0.00650506531809744 0.000381688531241544"
      rpy="1.66533453693773E-16 -3.12811319406522E-15 3.38963670212154E-32" />
    <parent
      link="FLL1" />
    <child
      link="FLL2" />
    <axis
      xyz="-1 0 0" />
  </joint>
  <link
    name="FLL3">
    <inertial>
      <origin
        xyz="-0.0024877 0.0015376 -0.001509"
        rpy="0 0 0" />
      <mass
        value="1.3954E-05" />
      <inertia
        ixx="9.0239E-11"
        ixy="-1.1755E-11"
        ixz="-2.5436E-11"
        iyy="8.3778E-11"
        iyz="-2.6868E-11"
        izz="1.2261E-10" />
    </inertial>
    <visual>
      <origin
        xyz="0 0 0"
        rpy="0 0 0" />
      <geometry>
        <mesh
          filename="package://SL_assem3/meshes/FLL3.obj" />
      </geometry>
      <material
        name="">
        <color
          rgba="0.69804 0.69804 0.69804 1" />
      </material>
    </visual>
    <collision>
      <origin
        xyz="0 0 0"
        rpy="0 0 0" />
      <geometry>
        <mesh
          filename="package://SL_assem3/meshes/FLL3.obj" />
      </geometry>
    </collision>
  </link>
  <joint
    name="FLqfb3"
    type="revolute">
    <origin
      xyz="0.00224999999999993 0.000311554448381016 -0.00108509622877155"
      rpy="-0.044951490450215 -2.22144512713175E-16 0" />
    <parent
      link="FLL2" />
    <child
      link="FLL3" />
    <axis
      xyz="0 0 -1" />
  </joint>
  <link
    name="Leg">
    <inertial>
      <origin
        xyz="-8.6736E-19 8.6736E-19 1.7347E-18"
        rpy="0 0 0" />
      <mass
        value="1.6993E-05" />
      <inertia
        ixx="2.0657E-10"
        ixy="9.954E-15"
        ixz="-1.1711E-14"
        iyy="1.0894E-10"
        iyz="9.3123E-11"
        izz="9.8198E-11" />
    </inertial>
    <visual>
      <origin
        xyz="0 0 0"
        rpy="0 0 0" />
      <geometry>
        <mesh
          filename="package://SL_assem3/meshes/Leg.obj" />
      </geometry>
      <material
        name="">
        <color
          rgba="1 1 1 1" />
      </material>
    </visual>
    <collision>
      <origin
        xyz="0 0 0"
        rpy="0 0 0" />
      <geometry>
        <mesh
          filename="package://SL_assem3/meshes/Leg.obj" />
      </geometry>
    </collision>
  </link>
  <joint
    name="LegJoint"
    type="fixed">
    <origin
      xyz="6E-05 0.0046437 -0.0048033"
      rpy="0 0 0" />
    <parent
      link="FLL3" />
    <child
      link="Leg" />
    <axis
      xyz="0 0 0" />
  </joint>

<!-- swing loop joint -->

 <loop_joint name="FLqs2" type="continuous">
    <axis xyz="0 0 -1" />
    <link1 link="Chassis" rpy="0 0 0" 
	xyz="0.01275466 -0.00012 0.00168999" />
    <link2 link="FLS2" rpy="0 0 0" xyz= "-0.00053, 0.00012, 0.0" />
 </loop_joint>

<!-- lift loop joint -->

 <loop_joint name="FLql2" type="continuous">
    <axis xyz="-1 0 0" />
    <link1 link="Chassis" rpy="0 0 0"
	 xyz="0.01050466 -0.00012 0.00043999"/>
    <link2 link="FLL2"  rpy="0 0 0" xyz= "0.0, 0.00036, 0.00058"/>
 </loop_joint>

<!-- SFB loop joint -->

<!-- <loop_joint  name="FLqfb2"  type="continuous">
    <axis xyz="0 -1 0" />
    <link1 link="FLS3" rpy="0 0 0" 
      xyz="-0.00205236 0.00598080 0.0"/> 
    <link2 link="FLL3" rpy="0 0 0"
      xyz="0.0 0.00598080 0.00165000"/>
 </loop_joint> -->
 
</robot>
