<?xml version="1.0"?>
<robot
  name="SL_assem4">
  <link
    name="Chassis">
    <inertial>
      <origin
        xyz="-1.708538631651E-06 -0.000168050643038979 -6.00502784529958E-05"
        rpy="0 0 0" />
      <mass
        value="0.000157823045150986" />
      <inertia
        ixx="3.14796267484832E-09"
        ixy="-5.17585240325789E-14"
        ixz="-2.63237617209499E-13"
        iyy="1.90314929516234E-08"
        iyz="-1.81916505888724E-12"
        izz="1.58879566734471E-08" />
    </inertial>
    <visual>
      <origin
        xyz="0 0 0"
        rpy="0 0 0" />
      <geometry>
        <mesh
          filename="package://SL_assem4/meshes/Chassis.obj" />
      </geometry>
      <material
        name="">
        <color
          rgba="0.752941176470588 0.752941176470588 0.752941176470588 1" />
      </material>
    </visual>
    <collision>
      <origin
        xyz="0 0 0"
        rpy="0 0 0" />
      <geometry>
        <mesh
          filename="package://SL_assem4/meshes/Chassis.obj" />
      </geometry>
    </collision>
  </link>
  <link
    name="FLS1">
    <inertial>
      <origin
        xyz="-4.4235E-17 0.0040837 0.0013542" rpy="0 0 0" />
      <mass value="8.1633E-06" />
      <inertia ixx="5.8035E-11" ixy="5.0179E-25" ixz="1.5712E-25" iyy="1.0937E-11" iyz="-1.4734E-11"
       		izz="4.7177E-11" />
    </inertial>
    <visual>
      <origin xyz="0 0 0" rpy="0 0 0" />
      <geometry>
        <mesh filename="package://SL_assem4/meshes/FLS1.obj" />
      </geometry>
      <material
        name="">
        <color rgba="0.69804 0.69804 0.69804 1" />
      </material>
    </visual>
      </link>
  <joint name="FLqsact" type="planar">
    <origin xyz="0.0132846598153906 -0.00845331587342392 -0.000498260011089041" rpy="0 0 0" />
    <parent link="Chassis" />
    <child  link="FLS1" />
    <axis   xyz="0 0 1" />
    <limit lower="-0.0005" upper="0.0005" />
  </joint>
  <link
    name="FLS2">
    <inertial>
      <origin xyz="0.00070289 -8.6332E-05 0.00010242" rpy="0 0 0" />
      <mass value="3.889E-06" />
      <inertia ixx="2.6158E-12" ixy="-5.7753E-13" ixz="-3.2642E-13" iyy="4.7809E-12" iyz="-8.2188E-14"
        izz="3.1897E-12" />
    </inertial>
    <visual>
      <origin xyz="0 0 0" rpy="0 0 0" />
      <geometry>
        <mesh filename="package://SL_assem4/meshes/FLS2.obj" />
      </geometry>
      <material
        name="">
        <color rgba="1 1 1 1" />
      </material>
    </visual>
  </link>
  <joint name="FLqs1" type="revolute">
    <origin xyz="0 0.0082133 0.0021883" rpy="0 0 0" />
    <parent link="FLS1" />
    <child link="FLS2" />
    <axis  xyz="0 0 1" />
    <limit lower="-pi/3" upper="pi/3" />
  </joint>

 <!-- <link
    name="FLS3">
    <inertial>
      <origin
        xyz="0.0014605 0.0018371 0.0030882"
        rpy="0 0 0" />
      <mass
        value="1.4269E-05" />
      <inertia
        ixx="1.206E-10"
        ixy="3.2785E-11"
        ixz="-2.9892E-11"
        iyy="8.3598E-11"
        iyz="2.1738E-11"
        izz="9.8829E-11" />
    </inertial>
    <visual>
      <origin
        xyz="0 0 0"
        rpy="0 0 0" />
      <geometry>
        <mesh
          filename="package://SL_assem4/meshes/FLS3.obj" />
      </geometry>
      <material
        name="">
        <color
          rgba="0.69804 0.69804 0.69804 1" />
      </material>
    </visual>
    <collision>
      <origin
        xyz="0 0 0"
        rpy="0 0 0" />
      <geometry>
        <mesh
          filename="package://SL_assem4/meshes/FLS3.obj" />
      </geometry>
    </collision>
  </link>
  <joint
    name="FLqfb1"
    type="revolute">
    <origin
      xyz="0.0015224 0.00012 -0.00125"
      rpy="0 0 0" />
    <parent
      link="FLS2" />
    <child
      link="FLS3" />
    <axis
      xyz="1 0 0" />
   </joint>
  <link
    name="FLL1">
    <inertial>
      <origin
        xyz="-0.00015469 0.0033385 5.8575E-05"
        rpy="0 0 0" />
      <mass
        value="6.1384E-06" />
      <inertia
        ixx="2.2433E-11"
        ixy="1.9915E-13"
        ixz="3.0682E-13"
        iyy="5.3665E-12"
        iyz="-1.829E-12"
        izz="2.4839E-11" />
    </inertial>
    <visual>
      <origin
        xyz="0 0 0"
        rpy="0 0 0" />
      <geometry>
        <mesh
          filename="package://SL_assem4/meshes/FLL1.obj" />
      </geometry>
      <material
        name="">
        <color
          rgba="0.69804 0.69804 0.69804 1" />
      </material>
    </visual>
    <collision>
      <origin
        xyz="0 0 0"
        rpy="0 0 0" />
      <geometry>
        <mesh
          filename="package://SL_assem4/meshes/FLL1.obj" />
      </geometry>
    </collision>
  </link>
  <joint
    name="FLqlact"
    type="prismatic">
    <origin
      xyz="0.0105046598153906 -0.00699822017852313 -0.000521698113120569"
      rpy="0 0 0" />
    <parent
      link="Chassis" />
    <child
      link="FLL1" />
    <axis
      xyz="0 1 0" />
    <limit lower="-0.0002" upper="0.0002" />
  </joint>
  <link
    name="FLL2">
    <inertial>
      <origin
        xyz="0.00011652 0.0001137 -0.0005651"
        rpy="0 0 0" />
      <mass
        value="4.2308E-06" />
      <inertia
        ixx="2.753E-12"
        ixy="-1.2143E-13"
        ixz="3.1854E-13"
        iyy="5.8098E-12"
        iyz="6.062E-13"
        izz="4.7043E-12" />
    </inertial>
    <visual>
      <origin
        xyz="0 0 0"
        rpy="0 0 0" />
      <geometry>
        <mesh
          filename="package://SL_assem4/meshes/FLL2.obj" />
      </geometry>
      <material
        name="">
        <color
          rgba="0.69804 0.69804 0.69804 1" />
      </material>
    </visual>
    <collision>
      <origin
        xyz="0 0 0"
        rpy="0 0 0" />
      <geometry>
        <mesh
          filename="package://SL_assem4/meshes/FLL2.obj" />
      </geometry>
    </collision>
  </link>
  <joint
    name="FLql1"
    type="revolute">
    <origin
      xyz="0 0.0065182 0.00038169"
      rpy="0 0 0" />
    <parent
      link="FLL1" />
    <child
      link="FLL2" />
    <axis
      xyz="1 0 0" />
   </joint>
  <link
    name="FLL3">
    <inertial>
      <origin
        xyz="-0.0024877 0.0015376 -0.001509"
        rpy="0 0 0" />
      <mass
        value="1.3954E-05" />
      <inertia
        ixx="9.0239E-11"
        ixy="-1.1755E-11"
        ixz="-2.5436E-11"
        iyy="8.3778E-11"
        iyz="-2.6868E-11"
        izz="1.2261E-10" />
    </inertial>
    <visual>
      <origin
        xyz="0 0 0"
        rpy="0 0 0" />
      <geometry>
        <mesh
          filename="package://SL_assem4/meshes/FLL3.obj" />
      </geometry>
      <material
        name="">
        <color
          rgba="0.69804 0.69804 0.69804 1" />
      </material>
    </visual>
    <collision>
      <origin
        xyz="0 0 0"
        rpy="0 0 0" />
      <geometry>
        <mesh
          filename="package://SL_assem4/meshes/FLL3.obj" />
      </geometry>
    </collision>
  </link>
  <joint
    name="FLqfb3"
    type="revolute">
    <origin
      xyz="0.00225 0.00036 -0.00107"
      rpy="0 0 0" />
    <parent
      link="FLL2" />
    <child
      link="FLL3" />
    <axis
      xyz="0 0 1" />
   </joint>
  <link
    name="Leg">
    <inertial>
      <origin
        xyz="1.001E-13 8.6736E-19 1.6653E-16"
        rpy="0 0 0" />
      <mass
        value="1.6993E-05" />
      <inertia
        ixx="2.0657E-10"
        ixy="9.954E-15"
        ixz="-1.1711E-14"
        iyy="1.0894E-10"
        iyz="9.3123E-11"
        izz="9.8198E-11" />
    </inertial>
    <visual>
      <origin
        xyz="0 0 0"
        rpy="0 0 0" />
      <geometry>
        <mesh
          filename="package://SL_assem4/meshes/Leg.obj" />
      </geometry>
      <material
        name="">
        <color
          rgba="1 1 1 1" />
      </material>
    </visual>
    <collision>
      <origin
        xyz="0 0 0"
        rpy="0 0 0" />
      <geometry>
        <mesh
          filename="package://SL_assem4/meshes/Leg.obj" />
      </geometry>
    </collision>
  </link>
  <joint
    name="LegJoint"
    type="fixed">
    <origin
      xyz="6.00000736484191E-05 0.00464367405164366 -0.0048032603867767"
      rpy="0 0 0" />
    <parent
      link="FLL3" />
    <child
      link="Leg" />
    <axis
      xyz="0 0 0" />
  </joint>-->

<!--<loop_joint name="FLqs2" type="continuous">
    <axis xyz="0 0 1" />
    <link1 link="Chassis" rpy="0 0 0" 
	xyz="0.01275466 -0.00012 0.00168999" />
    <link2 link="FLS2" rpy="0 0 0" xyz= "-0.00053, 0.00012, 0.0" />
 </loop_joint>
-->
<!--<loop_joint name="FLql2" type="continuous">
    <axis xyz="-1 0 0" />
    <link1 link="Chassis" rpy="0 0 0"
	 xyz="0.01050466 -0.00012 0.00043999"/>
    <link2 link="FLL2"  rpy="0 0 0" xyz= "0.0, 0.00036, 0.00058"/>
 </loop_joint>

<loop_joint  name="FLqfb2"  type="continuous">
    <axis xyz="0 -1 0" />
    <link1 link="FLS3" rpy="0 0 0" 
      xyz="-0.00205236 0.00598080 0.0"/> 
    <link2 link="FLL3" rpy="0 0 0"
      xyz="0.0 0.00598080 0.00165000"/>
 </loop_joint> -->
</robot>
