<?xml version="1.0"?>
<robot name="VibrationFoot_2D">

<link name="Foot">

    <inertial>
      <origin xyz="0 0 0" rpy="0 0 0" />
      <mass value="0.05" />
      <inertia ixx="1e-5" ixy="0" ixz="0" iyy="2e-5" iyz="0" izz="1e-5" />
    </inertial>

    <visual>
    <origin xyz="0 0 0" rpy="0 0 0" />
    <geometry>
      <box size="0.07 0.03 0.01"/>
      </geometry>
      <material name="Black"> 
        <color rgba="0 1 1 1" />
      </material>
    </visual>

    <collision>
      <origin xyz="-0.035 0.015 -0.005"/>
      <geometry>
        <sphere radius="0" />
      </geometry>
    </collision>

    <collision>
      <origin xyz="0.035 0.015 -0.005"/>
      <geometry>
        <sphere radius="0" />
      </geometry>
    </collision>

    <collision>
      <origin xyz="-0.035 -0.015 -0.005"/>
      <geometry>
        <sphere radius="0" />
      </geometry>
    </collision>

    <collision>
      <origin xyz="0.035 -0.015 -0.005"/>
      <geometry>
        <sphere radius="0" />
      </geometry>
    </collision>

 </link>

<link name="Mass">

    <inertial>
      <origin xyz="0 0 0" rpy="0 0 0" />
      <mass value=" 1" />
      <inertia ixx="1.5e-4" ixy="0" ixz="0"
        iyy="1.5e-4" iyz="0" izz="1.5e-4" />
    </inertial>

    <visual>
      <origin xyz="0 0 0" rpy="0 0 0" />
      <geometry>
        <box size="0.03 0.03 0.03"/>
      </geometry>
      <material name="Black"> 
        <color rgba="0 0 0 0" />
      </material>
    </visual>

</link>

<joint name="SpringLength" type="prismatic">

    <origin xyz="0 0 0.05" rpy="0 0 0" />
    <parent link="Foot" />
    <child link="Mass" />
    <axis xyz="0 0 1" />
    <dynamics damping="200"/> 

</joint>

<force_element name="MaterialSpring">

    <prismatic_spring stiffness="1e6" rest_length="0">
      <joint name="SpringLength" />
    </prismatic_spring>

</force_element>


<!--- Actuator Inputs -->

<transmission type="SimpleTransmission" name="VibrationMotor">
    <actuator name="PagerMotor" />
    <joint name="SpringLength" />
    <mechanicalReduction>1</mechanicalReduction>
</transmission>


</robot>