<?xml version="1.0"?>
<robot xmlns="http://drake.mit.edu"
 xmlns:xsi="http://www.w3.org/2001/XMLSchema-instance"
 xsi:schemaLocation="http://drake.mit.edu ../../doc/drakeURDF.xsd" name="FourBar">
  <link name="base_link">
    <inertial>
        <mass value="1"/>
        <inertia ixx="1"  ixy="0"  ixz="0" iyy="1" iyz="0" izz="1" />
        <origin xyz="0, 0, 0" rpy="0 0 0" /> 
    </inertial>
    <visual>
      <geometry>
        <cylinder length="3.6" radius="0.2"/>
      </geometry>
      <material>
        <color rgba=".6353 .6353 .6353 1"/>
      </material>
    </visual>
  </link>

  <link name="link_1">
    <inertial>
        <origin xyz="0, 0, 0.9" rpy="0 0 0" />
        <mass value="1"/>
        <inertia ixx="1"  ixy="0"  ixz="0" iyy="1" iyz="0" izz="1" />
    </inertial>
    <visual>
      <origin xyz="0 0 .9" rpy="0 0 0"/>
      <geometry>
        <cylinder length="1.8" radius="0.2"/>
      </geometry>
      <material>
        <color rgba=".6353 .6353 .6353 1"/>
      </material>
    </visual>
  </link>

  <link name="link_2">
    <inertial>
        <origin xyz="0, 0, 0.9" rpy="0 0 0" /> 
        <mass value="1"/>
        <inertia ixx="1"  ixy="0"  ixz="0" iyy="1" iyz="0" izz="1" />
    </inertial>
    <visual>
      <origin xyz="0 0 0.9" rpy="0 0 0"/>
      <geometry>
        <cylinder length="1.8" radius="0.2"/>
      </geometry>
      <material>
        <color rgba=".6353 .6353 .6353 1"/>
      </material>
    </visual>
  </link>

  <link name="link_3">
    <inertial>
        <origin xyz="0, 0, 0.9" rpy="0 0 0" />
        <mass value="1"/>
        <inertia ixx="1"  ixy="0"  ixz="0" iyy="1" iyz="0" izz="1" />
    </inertial>
    <visual>
      <origin xyz="0 0 0.9" rpy="0 0 0"/>
      <geometry>
        <cylinder length="1.8" radius="0.2"/>
      </geometry>
      <material>
        <color rgba=".6353 .6353 .6353 1"/>
      </material>
    </visual>
    <!--<collision>
      <origin xyz="0 0 2.6"/>
      <geometry>
        <sphere radius="0" />
      </geometry>
    </collision> -->
  </link> 

  <link name="link_4">
    <inertial>
        <origin xyz="0, 0, 0.9" rpy="0 0 0" />
        <mass value="1"/>
        <inertia ixx="1"  ixy="0"  ixz="0" iyy="1" iyz="0" izz="1" />
    </inertial>
    <visual>
      <origin xyz="0 0 0.9" rpy="0 0 0"/>
      <geometry>
        <cylinder length="1.8" radius="0.2"/>
      </geometry>
      <material>
        <color rgba=".6353 .6353 .6353 1"/>
      </material>
    </visual>
    <!--<collision>
      <origin xyz="0 0 2.6"/>
      <geometry>
        <sphere radius="0" />
      </geometry>
    </collision> -->
  </link> 

  <joint name="joint_0" type="continuous">
    <axis xyz="0 1 0"/>
    <parent link="base_link"/>
    <child link="link_1"/>
    <origin rpy="0 0 0" xyz="0 0 1.8"/>
    <dynamics damping="1"/>
    <limit lower="pi/11" upper="10*pi/11" />
  </joint>

  <joint name="joint_1" type="continuous">
    <axis xyz="0 1 0"/>
    <parent link="link_1"/>
    <child link="link_2"/>
    <origin rpy="0 0 0" xyz="0 0 1.8"/>
    <dynamics damping="1.1"/>
    <!--<limit lower="-pi" upper="pi" />-->
  </joint>

  <joint name="joint_2" type="continuous">
    <axis xyz="0 1 0"/>
    <parent link="link_2"/>
    <child link="link_3"/>
    <origin rpy="0 0 0" xyz="0 0 1.8"/>
    <dynamics damping="1.2"/>
    <!--<limit lower="pi/4" upper="5*pi/4" />-->
  </joint>

  <joint name="joint_3" type="continuous">
    <axis xyz="0 1 0"/>
    <parent link="link_3"/>
    <child link="link_4"/>
    <origin rpy="0 0 0" xyz="0 0 1.8"/>
    <dynamics damping="1.3"/>
    <!--<limit lower="pi/4" upper="5*pi/4" />-->
  </joint>

  <!--<loop_joint name="joint_3" type="continuous">
    <axis xyz="0 1 0"/>
    <link1 link="link_3" rpy="0 0 0" xyz="0 0 1.8"/>
    <link2 link="link_4" rpy="0 0 0" xyz="0 0 0"/>
    <dynamics stiffness="25" damping="1"/>
  </loop_joint>-->

<force_element name="k0">
  <torsional_spring stiffness="5" rest_angle="0">
    <joint name="joint_0" />
  </torsional_spring>
 </force_element>

 <force_element name="k1">
  <torsional_spring stiffness="0" rest_angle="0">
    <joint name="joint_1" />
   </torsional_spring>
 </force_element>

 <force_element name="k2">
  <torsional_spring stiffness="5" rest_angle="0">
    <joint name="joint_2" />
  </torsional_spring>
 </force_element>-->

  <force_element name="k3">
  <torsional_spring stiffness="0" rest_angle="0">
    <joint name="joint_3" />
  </torsional_spring>
 </force_element>-->


  <!--<transmission type="SimpleTransmission" name="joint_0_trans">
    <actuator name="control_torque" />
    <joint name="joint_0" />
    <mechanicalReduction>1</mechanicalReduction>
  </transmission>-->

</robot>
